2022-03-03 23:36:19,475 INFO    MainThread:29975 [internal.py:wandb_internal():92] W&B internal server running at pid: 29975, started at: 2022-03-03 23:36:19.475685
2022-03-03 23:36:19,480 INFO    WriterThread:29975 [datastore.py:open_for_write():77] open: /home/mohanakrishnan/code/LAnnamaria/quotes_for_posts_783/notebooks/wandb/run-20220303_233618-3icsoryz/run-3icsoryz.wandb
2022-03-03 23:36:19,484 DEBUG   SenderThread:29975 [sender.py:send():235] send: header
2022-03-03 23:36:19,485 DEBUG   SenderThread:29975 [sender.py:send():235] send: run
2022-03-03 23:36:48,390 DEBUG   HandlerThread:29975 [handler.py:handle_request():141] handle_request: shutdown
2022-03-03 23:36:48,390 INFO    HandlerThread:29975 [handler.py:finish():778] shutting down handler
2022-03-03 23:36:48,566 INFO    WriterThread:29975 [datastore.py:close():281] close: /home/mohanakrishnan/code/LAnnamaria/quotes_for_posts_783/notebooks/wandb/run-20220303_233618-3icsoryz/run-3icsoryz.wandb
2022-03-03 23:36:52,944 ERROR   SenderThread:29975 [retry.py:__call__():126] Retry attempt failed:
Traceback (most recent call last):
  File "/home/mohanakrishnan/.pyenv/versions/3.8.12/envs/quotes_for_posts_783/lib/python3.8/site-packages/urllib3/connection.py", line 174, in _new_conn
    conn = connection.create_connection(
  File "/home/mohanakrishnan/.pyenv/versions/3.8.12/envs/quotes_for_posts_783/lib/python3.8/site-packages/urllib3/util/connection.py", line 72, in create_connection
    for res in socket.getaddrinfo(host, port, family, socket.SOCK_STREAM):
  File "/home/mohanakrishnan/.pyenv/versions/3.8.12/lib/python3.8/socket.py", line 918, in getaddrinfo
    for res in _socket.getaddrinfo(host, port, family, type, proto, flags):
socket.gaierror: [Errno -3] Temporary failure in name resolution

During handling of the above exception, another exception occurred:

Traceback (most recent call last):
  File "/home/mohanakrishnan/.pyenv/versions/3.8.12/envs/quotes_for_posts_783/lib/python3.8/site-packages/urllib3/connectionpool.py", line 703, in urlopen
    httplib_response = self._make_request(
  File "/home/mohanakrishnan/.pyenv/versions/3.8.12/envs/quotes_for_posts_783/lib/python3.8/site-packages/urllib3/connectionpool.py", line 386, in _make_request
    self._validate_conn(conn)
  File "/home/mohanakrishnan/.pyenv/versions/3.8.12/envs/quotes_for_posts_783/lib/python3.8/site-packages/urllib3/connectionpool.py", line 1040, in _validate_conn
    conn.connect()
  File "/home/mohanakrishnan/.pyenv/versions/3.8.12/envs/quotes_for_posts_783/lib/python3.8/site-packages/urllib3/connection.py", line 358, in connect
    conn = self._new_conn()
  File "/home/mohanakrishnan/.pyenv/versions/3.8.12/envs/quotes_for_posts_783/lib/python3.8/site-packages/urllib3/connection.py", line 186, in _new_conn
    raise NewConnectionError(
urllib3.exceptions.NewConnectionError: <urllib3.connection.HTTPSConnection object at 0x7f28d4b8c850>: Failed to establish a new connection: [Errno -3] Temporary failure in name resolution

During handling of the above exception, another exception occurred:

Traceback (most recent call last):
  File "/home/mohanakrishnan/.pyenv/versions/3.8.12/envs/quotes_for_posts_783/lib/python3.8/site-packages/requests/adapters.py", line 440, in send
    resp = conn.urlopen(
  File "/home/mohanakrishnan/.pyenv/versions/3.8.12/envs/quotes_for_posts_783/lib/python3.8/site-packages/urllib3/connectionpool.py", line 785, in urlopen
    retries = retries.increment(
  File "/home/mohanakrishnan/.pyenv/versions/3.8.12/envs/quotes_for_posts_783/lib/python3.8/site-packages/urllib3/util/retry.py", line 592, in increment
    raise MaxRetryError(_pool, url, error or ResponseError(cause))
urllib3.exceptions.MaxRetryError: HTTPSConnectionPool(host='api.wandb.ai', port=443): Max retries exceeded with url: /graphql (Caused by NewConnectionError('<urllib3.connection.HTTPSConnection object at 0x7f28d4b8c850>: Failed to establish a new connection: [Errno -3] Temporary failure in name resolution'))

During handling of the above exception, another exception occurred:

Traceback (most recent call last):
  File "/home/mohanakrishnan/.pyenv/versions/3.8.12/envs/quotes_for_posts_783/lib/python3.8/site-packages/wandb/sdk/lib/retry.py", line 102, in __call__
    result = self._call_fn(*args, **kwargs)
  File "/home/mohanakrishnan/.pyenv/versions/3.8.12/envs/quotes_for_posts_783/lib/python3.8/site-packages/wandb/sdk/internal/internal_api.py", line 140, in execute
    return self.client.execute(*args, **kwargs)
  File "/home/mohanakrishnan/.pyenv/versions/3.8.12/envs/quotes_for_posts_783/lib/python3.8/site-packages/wandb/vendor/gql-0.2.0/wandb_gql/client.py", line 52, in execute
    result = self._get_result(document, *args, **kwargs)
  File "/home/mohanakrishnan/.pyenv/versions/3.8.12/envs/quotes_for_posts_783/lib/python3.8/site-packages/wandb/vendor/gql-0.2.0/wandb_gql/client.py", line 60, in _get_result
    return self.transport.execute(document, *args, **kwargs)
  File "/home/mohanakrishnan/.pyenv/versions/3.8.12/envs/quotes_for_posts_783/lib/python3.8/site-packages/wandb/vendor/gql-0.2.0/wandb_gql/transport/requests.py", line 38, in execute
    request = requests.post(self.url, **post_args)
  File "/home/mohanakrishnan/.pyenv/versions/3.8.12/envs/quotes_for_posts_783/lib/python3.8/site-packages/requests/api.py", line 117, in post
    return request('post', url, data=data, json=json, **kwargs)
  File "/home/mohanakrishnan/.pyenv/versions/3.8.12/envs/quotes_for_posts_783/lib/python3.8/site-packages/requests/api.py", line 61, in request
    return session.request(method=method, url=url, **kwargs)
  File "/home/mohanakrishnan/.pyenv/versions/3.8.12/envs/quotes_for_posts_783/lib/python3.8/site-packages/requests/sessions.py", line 529, in request
    resp = self.send(prep, **send_kwargs)
  File "/home/mohanakrishnan/.pyenv/versions/3.8.12/envs/quotes_for_posts_783/lib/python3.8/site-packages/requests/sessions.py", line 645, in send
    r = adapter.send(request, **kwargs)
  File "/home/mohanakrishnan/.pyenv/versions/3.8.12/envs/quotes_for_posts_783/lib/python3.8/site-packages/requests/adapters.py", line 519, in send
    raise ConnectionError(e, request=request)
requests.exceptions.ConnectionError: HTTPSConnectionPool(host='api.wandb.ai', port=443): Max retries exceeded with url: /graphql (Caused by NewConnectionError('<urllib3.connection.HTTPSConnection object at 0x7f28d4b8c850>: Failed to establish a new connection: [Errno -3] Temporary failure in name resolution'))
2022-03-03 23:36:58,170 INFO    SenderThread:29975 [dir_watcher.py:__init__():169] watching files in: /home/mohanakrishnan/code/LAnnamaria/quotes_for_posts_783/notebooks/wandb/run-20220303_233618-3icsoryz/files
2022-03-03 23:36:58,170 INFO    SenderThread:29975 [sender.py:_start_run_threads():812] run started: 3icsoryz with start time 1646346978
2022-03-03 23:36:58,170 INFO    SenderThread:29975 [sender.py:finish():1078] shutting down sender
2022-03-03 23:36:58,170 INFO    SenderThread:29975 [dir_watcher.py:finish():283] shutting down directory watcher
2022-03-03 23:36:59,170 INFO    SenderThread:29975 [dir_watcher.py:finish():313] scan: /home/mohanakrishnan/code/LAnnamaria/quotes_for_posts_783/notebooks/wandb/run-20220303_233618-3icsoryz/files
2022-03-03 23:36:59,170 INFO    SenderThread:29975 [dir_watcher.py:finish():327] scan save: /home/mohanakrishnan/code/LAnnamaria/quotes_for_posts_783/notebooks/wandb/run-20220303_233618-3icsoryz/files/config.yaml config.yaml
2022-03-03 23:36:59,171 INFO    SenderThread:29975 [file_pusher.py:finish():145] shutting down file pusher
2022-03-03 23:36:59,171 INFO    SenderThread:29975 [file_pusher.py:join():150] waiting for file pusher
2022-03-03 23:37:00,027 INFO    Thread-9  :29975 [upload_job.py:push():137] Uploaded file /home/mohanakrishnan/code/LAnnamaria/quotes_for_posts_783/notebooks/wandb/run-20220303_233618-3icsoryz/files/config.yaml
2022-03-03 23:37:01,917 INFO    MainThread:29975 [internal.py:handle_exit():82] Internal process exited
