2022-03-03 23:36:18,125 INFO    MainThread:29880 [wandb_setup.py:_flush():75] Loading settings from /home/mohanakrishnan/.config/wandb/settings
2022-03-03 23:36:18,125 INFO    MainThread:29880 [wandb_setup.py:_flush():75] Loading settings from /home/mohanakrishnan/code/LAnnamaria/quotes_for_posts_783/notebooks/wandb/settings
2022-03-03 23:36:18,125 INFO    MainThread:29880 [wandb_setup.py:_flush():75] Loading settings from environment variables: {}
2022-03-03 23:36:18,125 INFO    MainThread:29880 [wandb_setup.py:_flush():75] Inferring run settings from compute environment: {'program': '<python with no main file>'}
2022-03-03 23:36:18,125 INFO    MainThread:29880 [wandb_setup.py:_flush():75] Applying login settings: {'api_key': '***REDACTED***'}
2022-03-03 23:36:18,125 INFO    MainThread:29880 [wandb_setup.py:_flush():75] Applying login settings: {'api_key': '***REDACTED***'}
2022-03-03 23:36:18,125 INFO    MainThread:29880 [wandb_init.py:_log_setup():405] Logging user logs to /home/mohanakrishnan/code/LAnnamaria/quotes_for_posts_783/notebooks/wandb/run-20220303_233618-3icsoryz/logs/debug.log
2022-03-03 23:36:18,125 INFO    MainThread:29880 [wandb_init.py:_log_setup():406] Logging internal logs to /home/mohanakrishnan/code/LAnnamaria/quotes_for_posts_783/notebooks/wandb/run-20220303_233618-3icsoryz/logs/debug-internal.log
2022-03-03 23:36:18,125 INFO    MainThread:29880 [wandb_init.py:_jupyter_setup():355] configuring jupyter hooks <wandb.sdk.wandb_init._WandbInit object at 0x7f571439c130>
2022-03-03 23:36:18,126 INFO    MainThread:29880 [wandb_init.py:init():439] calling init triggers
2022-03-03 23:36:18,126 INFO    MainThread:29880 [wandb_init.py:init():442] wandb.init called with sweep_config: {}
config: {}
2022-03-03 23:36:18,126 INFO    MainThread:29880 [wandb_init.py:init():492] starting backend
2022-03-03 23:36:18,126 INFO    MainThread:29880 [backend.py:_multiprocessing_setup():99] multiprocessing start_methods=fork,spawn,forkserver, using: spawn
2022-03-03 23:36:18,272 INFO    MainThread:29880 [backend.py:ensure_launched():219] starting backend process...
2022-03-03 23:36:18,296 INFO    MainThread:29880 [backend.py:ensure_launched():224] started backend process with pid: 29975
2022-03-03 23:36:18,299 INFO    MainThread:29880 [wandb_init.py:init():501] backend started and connected
2022-03-03 23:36:18,314 INFO    MainThread:29880 [wandb_run.py:_label_probe_notebook():947] probe notebook
2022-03-03 23:36:18,314 INFO    MainThread:29880 [wandb_init.py:init():565] updated telemetry
2022-03-03 23:36:18,387 INFO    MainThread:29880 [wandb_init.py:init():596] communicating run to backend with 30 second timeout
2022-03-03 23:36:41,476 ERROR   Thread-5  :29880 [retry.py:__call__():126] Retry attempt failed:
Traceback (most recent call last):
  File "/home/mohanakrishnan/.pyenv/versions/3.8.12/envs/quotes_for_posts_783/lib/python3.8/site-packages/urllib3/connection.py", line 174, in _new_conn
    conn = connection.create_connection(
  File "/home/mohanakrishnan/.pyenv/versions/3.8.12/envs/quotes_for_posts_783/lib/python3.8/site-packages/urllib3/util/connection.py", line 72, in create_connection
    for res in socket.getaddrinfo(host, port, family, socket.SOCK_STREAM):
  File "/home/mohanakrishnan/.pyenv/versions/3.8.12/lib/python3.8/socket.py", line 918, in getaddrinfo
    for res in _socket.getaddrinfo(host, port, family, type, proto, flags):
socket.gaierror: [Errno -3] Temporary failure in name resolution

During handling of the above exception, another exception occurred:

Traceback (most recent call last):
  File "/home/mohanakrishnan/.pyenv/versions/3.8.12/envs/quotes_for_posts_783/lib/python3.8/site-packages/urllib3/connectionpool.py", line 703, in urlopen
    httplib_response = self._make_request(
  File "/home/mohanakrishnan/.pyenv/versions/3.8.12/envs/quotes_for_posts_783/lib/python3.8/site-packages/urllib3/connectionpool.py", line 386, in _make_request
    self._validate_conn(conn)
  File "/home/mohanakrishnan/.pyenv/versions/3.8.12/envs/quotes_for_posts_783/lib/python3.8/site-packages/urllib3/connectionpool.py", line 1040, in _validate_conn
    conn.connect()
  File "/home/mohanakrishnan/.pyenv/versions/3.8.12/envs/quotes_for_posts_783/lib/python3.8/site-packages/urllib3/connection.py", line 358, in connect
    conn = self._new_conn()
  File "/home/mohanakrishnan/.pyenv/versions/3.8.12/envs/quotes_for_posts_783/lib/python3.8/site-packages/urllib3/connection.py", line 186, in _new_conn
    raise NewConnectionError(
urllib3.exceptions.NewConnectionError: <urllib3.connection.HTTPSConnection object at 0x7f566d1bd2b0>: Failed to establish a new connection: [Errno -3] Temporary failure in name resolution

During handling of the above exception, another exception occurred:

Traceback (most recent call last):
  File "/home/mohanakrishnan/.pyenv/versions/3.8.12/envs/quotes_for_posts_783/lib/python3.8/site-packages/requests/adapters.py", line 440, in send
    resp = conn.urlopen(
  File "/home/mohanakrishnan/.pyenv/versions/3.8.12/envs/quotes_for_posts_783/lib/python3.8/site-packages/urllib3/connectionpool.py", line 785, in urlopen
    retries = retries.increment(
  File "/home/mohanakrishnan/.pyenv/versions/3.8.12/envs/quotes_for_posts_783/lib/python3.8/site-packages/urllib3/util/retry.py", line 592, in increment
    raise MaxRetryError(_pool, url, error or ResponseError(cause))
urllib3.exceptions.MaxRetryError: HTTPSConnectionPool(host='api.wandb.ai', port=443): Max retries exceeded with url: /graphql (Caused by NewConnectionError('<urllib3.connection.HTTPSConnection object at 0x7f566d1bd2b0>: Failed to establish a new connection: [Errno -3] Temporary failure in name resolution'))

During handling of the above exception, another exception occurred:

Traceback (most recent call last):
  File "/home/mohanakrishnan/.pyenv/versions/3.8.12/envs/quotes_for_posts_783/lib/python3.8/site-packages/wandb/sdk/lib/retry.py", line 102, in __call__
    result = self._call_fn(*args, **kwargs)
  File "/home/mohanakrishnan/.pyenv/versions/3.8.12/envs/quotes_for_posts_783/lib/python3.8/site-packages/wandb/sdk/internal/internal_api.py", line 140, in execute
    return self.client.execute(*args, **kwargs)
  File "/home/mohanakrishnan/.pyenv/versions/3.8.12/envs/quotes_for_posts_783/lib/python3.8/site-packages/wandb/vendor/gql-0.2.0/wandb_gql/client.py", line 52, in execute
    result = self._get_result(document, *args, **kwargs)
  File "/home/mohanakrishnan/.pyenv/versions/3.8.12/envs/quotes_for_posts_783/lib/python3.8/site-packages/wandb/vendor/gql-0.2.0/wandb_gql/client.py", line 60, in _get_result
    return self.transport.execute(document, *args, **kwargs)
  File "/home/mohanakrishnan/.pyenv/versions/3.8.12/envs/quotes_for_posts_783/lib/python3.8/site-packages/wandb/vendor/gql-0.2.0/wandb_gql/transport/requests.py", line 38, in execute
    request = requests.post(self.url, **post_args)
  File "/home/mohanakrishnan/.pyenv/versions/3.8.12/envs/quotes_for_posts_783/lib/python3.8/site-packages/requests/api.py", line 117, in post
    return request('post', url, data=data, json=json, **kwargs)
  File "/home/mohanakrishnan/.pyenv/versions/3.8.12/envs/quotes_for_posts_783/lib/python3.8/site-packages/requests/api.py", line 61, in request
    return session.request(method=method, url=url, **kwargs)
  File "/home/mohanakrishnan/.pyenv/versions/3.8.12/envs/quotes_for_posts_783/lib/python3.8/site-packages/requests/sessions.py", line 529, in request
    resp = self.send(prep, **send_kwargs)
  File "/home/mohanakrishnan/.pyenv/versions/3.8.12/envs/quotes_for_posts_783/lib/python3.8/site-packages/requests/sessions.py", line 645, in send
    r = adapter.send(request, **kwargs)
  File "/home/mohanakrishnan/.pyenv/versions/3.8.12/envs/quotes_for_posts_783/lib/python3.8/site-packages/requests/adapters.py", line 519, in send
    raise ConnectionError(e, request=request)
requests.exceptions.ConnectionError: HTTPSConnectionPool(host='api.wandb.ai', port=443): Max retries exceeded with url: /graphql (Caused by NewConnectionError('<urllib3.connection.HTTPSConnection object at 0x7f566d1bd2b0>: Failed to establish a new connection: [Errno -3] Temporary failure in name resolution'))
2022-03-03 23:36:46,600 ERROR   Thread-6  :29880 [retry.py:__call__():126] Retry attempt failed:
Traceback (most recent call last):
  File "/home/mohanakrishnan/.pyenv/versions/3.8.12/envs/quotes_for_posts_783/lib/python3.8/site-packages/urllib3/connection.py", line 174, in _new_conn
    conn = connection.create_connection(
  File "/home/mohanakrishnan/.pyenv/versions/3.8.12/envs/quotes_for_posts_783/lib/python3.8/site-packages/urllib3/util/connection.py", line 72, in create_connection
    for res in socket.getaddrinfo(host, port, family, socket.SOCK_STREAM):
  File "/home/mohanakrishnan/.pyenv/versions/3.8.12/lib/python3.8/socket.py", line 918, in getaddrinfo
    for res in _socket.getaddrinfo(host, port, family, type, proto, flags):
socket.gaierror: [Errno -3] Temporary failure in name resolution

During handling of the above exception, another exception occurred:

Traceback (most recent call last):
  File "/home/mohanakrishnan/.pyenv/versions/3.8.12/envs/quotes_for_posts_783/lib/python3.8/site-packages/urllib3/connectionpool.py", line 703, in urlopen
    httplib_response = self._make_request(
  File "/home/mohanakrishnan/.pyenv/versions/3.8.12/envs/quotes_for_posts_783/lib/python3.8/site-packages/urllib3/connectionpool.py", line 386, in _make_request
    self._validate_conn(conn)
  File "/home/mohanakrishnan/.pyenv/versions/3.8.12/envs/quotes_for_posts_783/lib/python3.8/site-packages/urllib3/connectionpool.py", line 1040, in _validate_conn
    conn.connect()
  File "/home/mohanakrishnan/.pyenv/versions/3.8.12/envs/quotes_for_posts_783/lib/python3.8/site-packages/urllib3/connection.py", line 358, in connect
    conn = self._new_conn()
  File "/home/mohanakrishnan/.pyenv/versions/3.8.12/envs/quotes_for_posts_783/lib/python3.8/site-packages/urllib3/connection.py", line 186, in _new_conn
    raise NewConnectionError(
urllib3.exceptions.NewConnectionError: <urllib3.connection.HTTPSConnection object at 0x7f566da13310>: Failed to establish a new connection: [Errno -3] Temporary failure in name resolution

During handling of the above exception, another exception occurred:

Traceback (most recent call last):
  File "/home/mohanakrishnan/.pyenv/versions/3.8.12/envs/quotes_for_posts_783/lib/python3.8/site-packages/requests/adapters.py", line 440, in send
    resp = conn.urlopen(
  File "/home/mohanakrishnan/.pyenv/versions/3.8.12/envs/quotes_for_posts_783/lib/python3.8/site-packages/urllib3/connectionpool.py", line 785, in urlopen
    retries = retries.increment(
  File "/home/mohanakrishnan/.pyenv/versions/3.8.12/envs/quotes_for_posts_783/lib/python3.8/site-packages/urllib3/util/retry.py", line 592, in increment
    raise MaxRetryError(_pool, url, error or ResponseError(cause))
urllib3.exceptions.MaxRetryError: HTTPSConnectionPool(host='api.wandb.ai', port=443): Max retries exceeded with url: /graphql (Caused by NewConnectionError('<urllib3.connection.HTTPSConnection object at 0x7f566da13310>: Failed to establish a new connection: [Errno -3] Temporary failure in name resolution'))

During handling of the above exception, another exception occurred:

Traceback (most recent call last):
  File "/home/mohanakrishnan/.pyenv/versions/3.8.12/envs/quotes_for_posts_783/lib/python3.8/site-packages/wandb/sdk/lib/retry.py", line 102, in __call__
    result = self._call_fn(*args, **kwargs)
  File "/home/mohanakrishnan/.pyenv/versions/3.8.12/envs/quotes_for_posts_783/lib/python3.8/site-packages/wandb/sdk/internal/internal_api.py", line 140, in execute
    return self.client.execute(*args, **kwargs)
  File "/home/mohanakrishnan/.pyenv/versions/3.8.12/envs/quotes_for_posts_783/lib/python3.8/site-packages/wandb/vendor/gql-0.2.0/wandb_gql/client.py", line 52, in execute
    result = self._get_result(document, *args, **kwargs)
  File "/home/mohanakrishnan/.pyenv/versions/3.8.12/envs/quotes_for_posts_783/lib/python3.8/site-packages/wandb/vendor/gql-0.2.0/wandb_gql/client.py", line 60, in _get_result
    return self.transport.execute(document, *args, **kwargs)
  File "/home/mohanakrishnan/.pyenv/versions/3.8.12/envs/quotes_for_posts_783/lib/python3.8/site-packages/wandb/vendor/gql-0.2.0/wandb_gql/transport/requests.py", line 38, in execute
    request = requests.post(self.url, **post_args)
  File "/home/mohanakrishnan/.pyenv/versions/3.8.12/envs/quotes_for_posts_783/lib/python3.8/site-packages/requests/api.py", line 117, in post
    return request('post', url, data=data, json=json, **kwargs)
  File "/home/mohanakrishnan/.pyenv/versions/3.8.12/envs/quotes_for_posts_783/lib/python3.8/site-packages/requests/api.py", line 61, in request
    return session.request(method=method, url=url, **kwargs)
  File "/home/mohanakrishnan/.pyenv/versions/3.8.12/envs/quotes_for_posts_783/lib/python3.8/site-packages/requests/sessions.py", line 529, in request
    resp = self.send(prep, **send_kwargs)
  File "/home/mohanakrishnan/.pyenv/versions/3.8.12/envs/quotes_for_posts_783/lib/python3.8/site-packages/requests/sessions.py", line 645, in send
    r = adapter.send(request, **kwargs)
  File "/home/mohanakrishnan/.pyenv/versions/3.8.12/envs/quotes_for_posts_783/lib/python3.8/site-packages/requests/adapters.py", line 519, in send
    raise ConnectionError(e, request=request)
requests.exceptions.ConnectionError: HTTPSConnectionPool(host='api.wandb.ai', port=443): Max retries exceeded with url: /graphql (Caused by NewConnectionError('<urllib3.connection.HTTPSConnection object at 0x7f566da13310>: Failed to establish a new connection: [Errno -3] Temporary failure in name resolution'))
2022-03-03 23:36:48,389 INFO    MainThread:29880 [interface_shared.py:_communicate_run():322] couldn't get run from backend
2022-03-03 23:36:48,389 ERROR   MainThread:29880 [wandb_init.py:init():601] backend process timed out
2022-03-03 23:36:48,389 ERROR   MainThread:29880 [wandb_init.py:init():610] encountered error: Error communicating with wandb process
try: wandb.init(settings=wandb.Settings(start_method='fork'))
or:  wandb.init(settings=wandb.Settings(start_method='thread'))
For more info see: https://docs.wandb.ai/library/init#init-start-error
2022-03-03 23:37:02,144 INFO    MainThread:29880 [wandb_init.py:teardown():253] tearing down wandb.init
